Workbook

Sheet 🔐 START
B7: 🏠 LIFE MANAGEMENT DASHBOARD
B8: Your Complete Personal Operating System
D16: 🔒 ENTER PASSWORD TO ACCESS
D17: Type your password in the yellow cell below and press Enter
D19: =IF(E18="","",IF(E18="life2025","✅ ACCESS GRANTED — Navigate to 🏠 HOME tab","❌ Incorrect password. Try again."))
D20: Default password: life2025
D21: After entering the correct password, click the 🏠 HOME tab below
B25: WHAT'S INSIDE THIS WORKBOOK
B26: 💰 Financial Tracking | F26: 🎯 Goal Management | J26: ✅ Habit Tracker
B27: Income, Expenses, Budget, Recurring Bills | F27: Track 12+ goals with progress bars | J27: 31-day daily grid with streaks & charts
B29: 📝 Task Management | F29: 🏃 Health & Wellness | J29: 📊 Analytics
B30: Kanban board + Eisenhower priority matrix | F30: Weight, sleep, mood, exercise trends | J30: Live KPIs + 6-month performance charts
B33: Life Management Dashboard • v2.0 • 20 Modules • 244+ Formulas

Sheet 🏠 HOME
B2: 🏠 LIFE MANAGEMENT DASHBOARD — Navigation Hub
B3: Click any card below to jump to that module • All data is live and connected
B7: ⚙️ SETUP | F7: 📊 DASHBOARD | J7: 📥 INCOME | N7: 📤 EXPENSES
B8: Configure categories & dropdowns | F8: Live KPIs — income, goals, habits | J8: Log all income sources | N8: Track every expense + categories
B9: → Click tab: SETUP | F9: → Click tab: DASHBOARD | J9: → Click tab: INCOME | N9: → Click tab: EXPENSES
B13: 📋 BUDGET | F13: 💼 WEALTH | J13: 📈 INVESTMENTS | N13: 🔄 RECURRING
B14: Monthly budget vs actual analysis | F14: Savings · Debt · Net Worth | J14: Portfolio + compound growth forecast | N14: Subscriptions & recurring bills
B15: → Click tab: BUDGET | F15: → Click tab: WEALTH | J15: → Click tab: INVESTMENTS | N15: → Click tab: RECURRING
B19: 🎯 GOALS | F19: ✅ HABITS | J19: 🗓️ CALENDAR | N19: ⏰ WEEKLY PLAN
B20: Track 12 goals with progress % | F20: 31-day daily habit grid + streaks | J20: Monthly calendar + weekly planner | N20: Hour-by-hour weekly schedule
B21: → Click tab: GOALS | F21: → Click tab: HABITS | J21: → Click tab: CALENDAR | N21: → Click tab: WEEKLY PLAN
B25: 📝 TASKS | F25: ⚡ PRIORITY | J25: 💰 NET WORTH | N25: 🏃 HEALTH
B26: Task list with priority & status | F26: Eisenhower Matrix + Kanban board | J26: Assets vs liabilities over time | N26: Weight · Sleep · Mood · Exercise
B27: → Click tab: TASKS | F27: → Click tab: PRIORITY | J27: → Click tab: NET WORTH | N27: → Click tab: HEALTH
B31: 🍽️ MEALS | F31: 📊 ANALYTICS | J31: 📖 USER GUIDE
B32: Meal planner + grocery list | F32: 6-month performance trend charts | J32: How to use this workbook
B33: → Click tab: MEALS | F33: → Click tab: ANALYTICS | J33: → Click tab: USER GUIDE
B39: 📊 LIVE SNAPSHOT — Key numbers from across the workbook
B40: Total Income | F40: Total Expenses | J40: Active Goals | N40: Tasks Done
B41: =IFERROR(SUM(INCOME!E4:E18),0) -> 31422.5 | F41: =IFERROR(SUM(EXPENSES!D4:D28),0) -> 6187.98 | J41: =IFERROR(COUNTIF(GOALS!G5:G16,"In Progress"),0) -> 11 | N41: =IFERROR(COUNTIF(TASKS!F5:F24,"Completed"),0) -> 4

Sheet SETUP
A1: ⚙️ SYSTEM SETUP — Edit category lists here (used by all dropdowns)
A2: These lists power every dropdown in the workbook. Expand any list by adding rows below.
B3: Expense Categories | C3: Income Sources | D3: Goal Types | E3: Habit Categories | F3: Task Categories | G3: Priority Levels | H3: Status Options | I3: Frequency Options
B4: Housing | C4: Salary | D4: Financial | E4: Health | F4: Work | G4: Critical | H4: Not Started | I4: Daily
B5: Food & Dining | C5: Freelance | D5: Health & Fitness | E5: Fitness | F5: Personal | G5: High | H5: In Progress | I5: Weekly
B6: Transportation | C6: Business | D6: Career | E6: Learning | F6: Health | G6: Medium | H6: Completed | I6: Bi-Weekly
B7: Healthcare | C7: Investments | D7: Personal Development | E7: Mindfulness | F7: Finance | G7: Low | H7: On Hold | I7: Monthly
B8: Entertainment | C8: Rental | D8: Relationships | E8: Productivity | F8: Home | G8: Someday | H8: Cancelled | I8: Quarterly
B9: Shopping | C9: Side Hustle | D9: Travel | E9: Social | F9: Learning | I9: Annually
B10: Education | C10: Bonus | D10: Education | E10: Finance | F10: Social
B11: Utilities | C11: Gifts | D11: Hobbies | E11: Creativity | F11: Project
B12: Insurance | C12: Other | D12: Other | E12: Sleep | F12: Errands
B13: Personal Care | E13: Nutrition | F13: Other
B14: Travel
B15: Subscriptions
B16: Savings
B17: Debt Payment
B18: Other

Sheet DASHBOARD
A1: 📊 EXECUTIVE DASHBOARD — Live overview from all modules
A2: All values auto-calculate from data entered in other sheets. No manual entry needed here.
A4: 💰 FINANCIAL SNAPSHOT
A6: Monthly Income | D6: Monthly Expenses | G6: Net Savings | J6: Savings Rate
A7: =IFERROR(SUM(INCOME!E4:E18),0) -> 31422.5 | D7: =IFERROR(SUM(EXPENSES!D4:D28),0) -> 6187.98 | G7: =IFERROR(SUM(INCOME!E4:E18)-SUM(EXPENSES!D4:D28),0) -> 25234.52 | J7: =IFERROR((SUM(INCOME!E4:E18)-SUM(EXPENSES!D4:D28))/SUM(INCOME!E4:E18),0) -> 0.80307168
A10: 🎯 GOALS & PRODUCTIVITY
A12: Active Goals | D12: Goals Completed | G12: Tasks Completed | J12: Habit Completion
A13: =IFERROR(COUNTIF(GOALS!G5:G16,"In Progress"),0) -> 11 | D13: =IFERROR(COUNTIF(GOALS!G5:G16,"Completed"),0) -> 1 | G13: =IFERROR(COUNTIF(TASKS!F5:F24,"Completed"),0) -> 4 | J13: =IFERROR(COUNTIF(HABITS!D4:AH18,"✓")/(15*31),0) -> 0.69247312
A16: 🏃 HEALTH SNAPSHOT
A18: Avg Weight (lbs) | D18: Avg Sleep (hrs) | G18: Avg Mood (1-10) | J18: Exercise Days
A19: =IFERROR(AVERAGE(HEALTH!C5:C24),0) -> 183.01 | D19: =IFERROR(AVERAGE(HEALTH!H5:H24),0) -> 7.675 | G19: =IFERROR(AVERAGE(HEALTH!I5:I24),0) -> 8.15 | J19: =IFERROR(COUNTIF(HEALTH!F5:F24,">0"),0) -> 16
A22: 📈 MONTHLY TREND DATA (Income · Expenses · Savings · Net Worth)
A23: Month | C23: Income | E23: Expenses | G23: Savings | I23: Net Worth
A24: Jan 2025 | C24: 5000 | E24: 3450 | G24: =C24-E24 -> 1550 | I24: 42000
A25: Feb 2025 | C25: 5000 | E25: 3200 | G25: =C25-E25 -> 1800 | I25: 42500
A26: Mar 2025 | C26: 5350 | E26: 3600 | G26: =C26-E26 -> 1750 | I26: 43200
A27: Apr 2025 | C27: 5000 | E27: 3100 | G27: =C27-E27 -> 1900 | I27: 44100
A28: May 2025 | C28: 5500 | E28: 3400 | G28: =C28-E28 -> 2100 | I28: 45000
A29: Jun 2025 | C29: 5000 | E29: 3250 | G29: =C29-E29 -> 1750 | I29: 46200

Sheet INCOME
A1: 📥 INCOME TRACKER — Log all income sources
A2: Category dropdown auto-validates. Amount feeds Dashboard & Budget sheets.
A3: # | B3: Date | C3: Description | D3: Category | E3: Amount | F3: Account | G3: Tax Status | H3: Notes
A4: 1 | B4: 2025-01-01 | C4: Monthly Salary — January | D4: Salary | E4: 4500 | F4: Chase Checking | G4: Taxable | H4: Regular paycheck
A5: 2 | B5: 2025-01-08 | C5: Web Design — Client A | D5: Freelance | E5: 350 | F5: Chase Checking | G5: Self-Employed | H5: Invoice #001
A6: 3 | B6: 2025-01-10 | C6: Dividend — Fidelity Portfolio | D6: Investments | E6: 82.5 | F6: Fidelity Broker | G6: Taxable | H6: Q4 dividends
A7: 4 | B7: 2025-01-14 | C7: Side Project Referral Fee | D7: Side Hustle | E7: 200 | F7: Chase Checking | G7: Self-Employed
A8: 5 | B8: 2025-02-01 | C8: Monthly Salary — February | D8: Salary | E8: 4500 | F8: Chase Checking | G8: Taxable
A9: 6 | B9: 2025-02-12 | C9: Freelance Writing — Blog | D9: Freelance | E9: 150 | F9: Chase Checking | G9: Self-Employed | H9: Client B
A10: 7 | B10: 2025-02-18 | C10: Stock Sale Proceeds | D10: Investments | E10: 420 | F10: Fidelity Broker | G10: Taxable | H10: AAPL partial
A11: 8 | B11: 2025-03-01 | C11: Monthly Salary — March | D11: Salary | E11: 4500 | F11: Chase Checking | G11: Taxable
A12: 9 | B12: 2025-03-05 | C12: Q1 Performance Bonus | D12: Bonus | E12: 800 | F12: Chase Checking | G12: Taxable | H12: Q1 review
A13: 10 | B13: 2025-03-15 | C13: Freelance Design — Logo Pack | D13: Freelance | E13: 500 | F13: Chase Checking | G13: Self-Employed | H13: Client C
A14: 11 | B14: 2025-04-01 | C14: Monthly Salary — April | D14: Salary | E14: 4500 | F14: Chase Checking | G14: Taxable
A15: 12 | B15: 2025-04-20 | C15: Rental Sublease Income | D15: Rental | E15: 600 | F15: Chase Checking | G15: Taxable | H15: Short-term
A16: 13 | B16: 2025-05-01 | C16: Monthly Salary — May | D16: Salary | E16: 5000 | F16: Chase Checking | G16: Taxable | H16: Raise effective
A17: 14 | B17: 2025-05-10 | C17: Online Course Sales | D17: Side Hustle | E17: 320 | F17: PayPal | G17: Self-Employed | H17: Gumroad
A18: 15 | B18: 2025-06-01 | C18: Monthly Salary — June | D18: Salary | E18: 5000 | F18: Chase Checking | G18: Taxable
A19: TOTAL INCOME | E19: =SUM(E4:E18) -> 31422.5
A22: Category | C22: Total | D22: % of Total | E22: # Transactions
A23: Salary | C23: =SUMIF(D4:D18,A23,E4:E18) -> 28000 | D23: =IFERROR(C23/E19,0) -> 0.89108123 | E23: =COUNTIF(D4:D18,A23) -> 6
A24: Freelance | C24: =SUMIF(D4:D18,A24,E4:E18) -> 1000 | D24: =IFERROR(C24/E19,0) -> 0.03182433 | E24: =COUNTIF(D4:D18,A24) -> 3
A25: Business | C25: =SUMIF(D4:D18,A25,E4:E18) -> 0 | D25: =IFERROR(C25/E19,0) -> 0 | E25: =COUNTIF(D4:D18,A25) -> 0
A26: Investments | C26: =SUMIF(D4:D18,A26,E4:E18) -> 502.5 | D26: =IFERROR(C26/E19,0) -> 0.015991726 | E26: =COUNTIF(D4:D18,A26) -> 2
A27: Rental | C27: =SUMIF(D4:D18,A27,E4:E18) -> 600 | D27: =IFERROR(C27/E19,0) -> 0.019094598 | E27: =COUNTIF(D4:D18,A27) -> 1
A28: Side Hustle | C28: =SUMIF(D4:D18,A28,E4:E18) -> 520 | D28: =IFERROR(C28/E19,0) -> 0.016548651 | E28: =COUNTIF(D4:D18,A28) -> 2
A29: Bonus | C29: =SUMIF(D4:D18,A29,E4:E18) -> 800 | D29: =IFERROR(C29/E19,0) -> 0.025459464 | E29: =COUNTIF(D4:D18,A29) -> 1
A30: Gifts | C30: =SUMIF(D4:D18,A30,E4:E18) -> 0 | D30: =IFERROR(C30/E19,0) -> 0 | E30: =COUNTIF(D4:D18,A30) -> 0
A31: Other | C31: =SUMIF(D4:D18,A31,E4:E18) -> 0 | D31: =IFERROR(C31/E19,0) -> 0 | E31: =COUNTIF(D4:D18,A31) -> 0

Sheet EXPENSES
A1: 📤 EXPENSE TRACKER — Log every expense
A2: Category dropdown links to SETUP. Totals feed Budget & Analytics automatically.
A3: # | B3: Date | C3: Description | D3: Amount | E3: Category | F3: Payment Method | G3: Account | H3: Notes
A4: 1 | B4: 2025-01-02 | C4: Rent — January | D4: 1500 | E4: Housing | F4: Bank Transfer | G4: Chase Checking | H4: Monthly rent
A5: 2 | B5: 2025-01-03 | C5: Whole Foods Groceries | D5: 124 | E5: Food & Dining | F5: Debit Card | G5: Chase Checking | H5: Weekly shop
A6: 3 | B6: 2025-01-04 | C6: Netflix | D6: 15.99 | E6: Subscriptions | F6: Credit Card | G6: Citi Rewards
A7: 4 | B7: 2025-01-05 | C7: Gas — Shell | D7: 55 | E7: Transportation | F7: Credit Card | G7: Citi Rewards | H7: Full tank
A8: 5 | B8: 2025-01-06 | C8: Gym — Equinox | D8: 40 | E8: Healthcare | F8: Bank Transfer | G8: Chase Checking | H8: Monthly
A9: 6 | B9: 2025-01-08 | C9: Dinner — Nobu | D9: 78 | E9: Food & Dining | F9: Credit Card | G9: Citi Rewards | H9: Date night
A10: 7 | B10: 2025-01-10 | C10: Electric Bill | D10: 95 | E10: Utilities | F10: Bank Transfer | G10: Chase Checking
A11: 8 | B11: 2025-01-12 | C11: Amazon — Books | D11: 45 | E11: Shopping | F11: Credit Card | G11: Citi Rewards | H11: 3 books
A12: 9 | B12: 2025-01-15 | C12: Car Insurance — Geico | D12: 120 | E12: Insurance | F12: Bank Transfer | G12: Chase Checking | H12: Monthly
A13: 10 | B13: 2025-01-16 | C13: Uber Rides | D13: 32 | E13: Transportation | F13: Credit Card | G13: Citi Rewards | H13: 5 rides
A14: 11 | B14: 2025-01-18 | C14: Spotify | D14: 9.99 | E14: Subscriptions | F14: Credit Card | G14: Citi Rewards
A15: 12 | B15: 2025-01-20 | C15: Trader Joe's Groceries | D15: 110 | E15: Food & Dining | F15: Debit Card | G15: Chase Checking
A16: 13 | B16: 2025-01-22 | C16: Phone Bill — Verizon | D16: 65 | E16: Utilities | F16: Bank Transfer | G16: Chase Checking
A17: 14 | B17: 2025-01-25 | C17: Clothing — Banana Republic | D17: 89 | E17: Shopping | F17: Credit Card | G17: Citi Rewards | H17: Work clothes
A18: 15 | B18: 2025-01-28 | C18: Internet — Comcast | D18: 80 | E18: Utilities | F18: Bank Transfer | G18: Chase Checking
A19: 16 | B19: 2025-02-02 | C19: Rent — February | D19: 1500 | E19: Housing | F19: Bank Transfer | G19: Chase Checking
A20: 17 | B20: 2025-02-05 | C20: Whole Foods Groceries | D20: 138 | E20: Food & Dining | F20: Debit Card | G20: Chase Checking
A21: 18 | B21: 2025-02-08 | C21: Gym | D21: 40 | E21: Healthcare | F21: Bank Transfer | G21: Chase Checking
A22: 19 | B22: 2025-02-10 | C22: Dentist Visit | D22: 80 | E22: Healthcare | F22: Credit Card | G22: Citi Rewards | H22: Cleaning
A23: 20 | B23: 2025-02-14 | C23: Valentine's Dinner | D23: 145 | E23: Food & Dining | F23: Credit Card | G23: Citi Rewards
A24: 21 | B24: 2025-02-15 | C24: Car Insurance | D24: 120 | E24: Insurance | F24: Bank Transfer | G24: Chase Checking
A25: 22 | B25: 2025-02-18 | C25: Udemy Course | D25: 30 | E25: Education | F25: Credit Card | G25: Citi Rewards | H25: Python course
A26: 23 | B26: 2025-02-20 | C26: Gas | D26: 58 | E26: Transportation | F26: Credit Card | G26: Citi Rewards
A27: 24 | B27: 2025-03-02 | C27: Rent — March | D27: 1500 | E27: Housing | F27: Bank Transfer | G27: Chase Checking
A28: 25 | B28: 2025-03-06 | C28: Groceries | D28: 118 | E28: Food & Dining | F28: Debit Card | G28: Chase Checking
A29: TOTAL EXPENSES | D29: =SUM(D4:D28) -> 6187.98
A31: 📊 SPENDING BY CATEGORY
A32: Category | C32: Total Spent | D32: % of Total | E32: Monthly Budget | F32: Over/Under
A33: Housing | C33: =SUMIF(E4:E28,A33,D4:D28) -> 4500 | D33: =IFERROR(C33/D29,0) -> 0.72721631 | E33: 1500 | F33: =E33-C33 -> -3000
A34: Food & Dining | C34: =SUMIF(E4:E28,A34,D4:D28) -> 713 | D34: =IFERROR(C34/D29,0) -> 0.11522338 | E34: 400 | F34: =E34-C34 -> -313
A35: Transportation | C35: =SUMIF(E4:E28,A35,D4:D28) -> 145 | D35: =IFERROR(C35/D29,0) -> 0.023432526 | E35: 200 | F35: =E35-C35 -> 55
A36: Healthcare | C36: =SUMIF(E4:E28,A36,D4:D28) -> 160 | D36: =IFERROR(C36/D29,0) -> 0.02585658 | E36: 150 | F36: =E36-C36 -> -10
A37: Entertainment | C37: =SUMIF(E4:E28,A37,D4:D28) -> 0 | D37: =IFERROR(C37/D29,0) -> 0 | E37: 100 | F37: =E37-C37 -> 100
A38: Shopping | C38: =SUMIF(E4:E28,A38,D4:D28) -> 134 | D38: =IFERROR(C38/D29,0) -> 0.021654886 | E38: 150 | F38: =E38-C38 -> 16
A39: Education | C39: =SUMIF(E4:E28,A39,D4:D28) -> 30 | D39: =IFERROR(C39/D29,0) -> 0.0048481088 | E39: 50 | F39: =E39-C39 -> 20
A40: Utilities | C40: =SUMIF(E4:E28,A40,D4:D28) -> 240 | D40: =IFERROR(C40/D29,0) -> 0.03878487 | E40: 200 | F40: =E40-C40 -> -40
A41: Insurance | C41: =SUMIF(E4:E28,A41,D4:D28) -> 240 | D41: =IFERROR(C41/D29,0) -> 0.03878487 | E41: 120 | F41: =E41-C41 -> -120
...

Sheet BUDGET
A1: 📋 BUDGET PLANNER — Monthly Budget vs Actual (Q1 2025)
A2: Set monthly budgets below. Green = On Track ✅, Red = Over Budget ⚠️
A4: Category | B4: Monthly Budget | C4: Jan Actual | D4: Feb Actual | E4: Mar Actual | F4: YTD Spent | G4: Status
A5: Housing | B5: 1500 | C5: 1500 | D5: 1500 | E5: 1500 | F5: =SUM(C5:E5) -> 4500 | G5: =IF(F5<=B5*3,"✅ On Track","⚠️ Over Budget") -> ✅ On Track
A6: Food & Dining | B6: 400 | C6: 402 | D6: 423 | E6: 358 | F6: =SUM(C6:E6) -> 1183 | G6: =IF(F6<=B6*3,"✅ On Track","⚠️ Over Budget") -> ✅ On Track
A7: Transportation | B7: 200 | C7: 182 | D7: 218 | E7: 176 | F7: =SUM(C7:E7) -> 576 | G7: =IF(F7<=B7*3,"✅ On Track","⚠️ Over Budget") -> ✅ On Track
A8: Healthcare | B8: 150 | C8: 120 | D8: 200 | E8: 120 | F8: =SUM(C8:E8) -> 440 | G8: =IF(F8<=B8*3,"✅ On Track","⚠️ Over Budget") -> ✅ On Track
A9: Entertainment | B9: 100 | C9: 98 | D9: 78 | E9: 110 | F9: =SUM(C9:E9) -> 286 | G9: =IF(F9<=B9*3,"✅ On Track","⚠️ Over Budget") -> ✅ On Track
A10: Shopping | B10: 150 | C10: 134 | D10: 89 | E10: 118 | F10: =SUM(C10:E10) -> 341 | G10: =IF(F10<=B10*3,"✅ On Track","⚠️ Over Budget") -> ✅ On Track
A11: Education | B11: 50 | C11: 0 | D11: 30 | E11: 0 | F11: =SUM(C11:E11) -> 30 | G11: =IF(F11<=B11*3,"✅ On Track","⚠️ Over Budget") -> ✅ On Track
A12: Utilities | B12: 200 | C12: 240 | D12: 213 | E12: 198 | F12: =SUM(C12:E12) -> 651 | G12: =IF(F12<=B12*3,"✅ On Track","⚠️ Over Budget") -> ⚠️ Over Budget
A13: Insurance | B13: 120 | C13: 120 | D13: 120 | E13: 120 | F13: =SUM(C13:E13) -> 360 | G13: =IF(F13<=B13*3,"✅ On Track","⚠️ Over Budget") -> ✅ On Track
A14: Personal Care | B14: 80 | C14: 72 | D14: 65 | E14: 88 | F14: =SUM(C14:E14) -> 225 | G14: =IF(F14<=B14*3,"✅ On Track","⚠️ Over Budget") -> ✅ On Track
A15: Subscriptions | B15: 50 | C15: 25.98 | D15: 25.98 | E15: 25.98 | F15: =SUM(C15:E15) -> 77.94 | G15: =IF(F15<=B15*3,"✅ On Track","⚠️ Over Budget") -> ✅ On Track
A16: Savings | B16: 600 | C16: 600 | D16: 600 | E16: 600 | F16: =SUM(C16:E16) -> 1800 | G16: =IF(F16<=B16*3,"✅ On Track","⚠️ Over Budget") -> ✅ On Track
... A18: Other | B18: 100 | C18: 80 | D18: 45 | E18: 92 | F18: =SUM(C18:E18) -> 217 | G18: =IF(F18<=B18*3,"✅ On Track","⚠️ Over Budget") -> ✅ On Track
A19: TOTALS | B19: =SUM(B5:B18) -> 3850 | C19: =SUM(C5:C18) -> 3723.98 | D19: =SUM(D5:D18) -> 3756.98 | E19: =SUM(E5:E18) -> 3655.98 | F19: =SUM(F5:F18) -> 11136.94
A21: 📊 Q1 BUDGET vs ACTUAL COMPARISON
A22: Category | B22: Q1 Budget | C22: Q1 Actual | D22: Variance | E22: % Used
A23: Housing | B23: 4500 | C23: =SUM(C5:E5) -> 4500 | D23: =B23-C23 -> 0 | E23: =IFERROR(C23/B23,0) -> 1
A24: Food & Dining | B24: 1200 | C24: =SUM(C6:E6) -> 1183 | D24: =B24-C24 -> 17 | E24: =IFERROR(C24/B24,0) -> 0.98583333
A25: Transportation | B25: 600 | C25: =SUM(C7:E7) -> 576 | D25: =B25-C25 -> 24 | E25: =IFERROR(C25/B25,0) -> 0.96
A26: Healthcare | B26: 450 | C26: =SUM(C8:E8) -> 440 | D26: =B26-C26 -> 10 | E26: =IFERROR(C26/B26,0) -> 0.97777778
A27: Entertainment | B27: 300 | C27: =SUM(C9:E9) -> 286 | D27: =B27-C27 -> 14 | E27: =IFERROR(C27/B27,0) -> 0.95333333
A28: Shopping | B28: 450 | C28: =SUM(C10:E10) -> 341 | D28: =B28-C28 -> 109 | E28: =IFERROR(C28/B28,0) -> 0.75777778
A29: Education | B29: 150 | C29: =SUM(C11:E11) -> 30 | D29: =B29-C29 -> 120 | E29: =IFERROR(C29/B29,0) -> 0.2
A30: Utilities | B30: 600 | C30: =SUM(C12:E12) -> 651 | D30: =B30-C30 -> -51 | E30: =IFERROR(C30/B30,0) -> 1.085
A31: Insurance | B31: 360 | C31: =SUM(C13:E13) -> 360 | D31: =B31-C31 -> 0 | E31: =IFERROR(C31/B31,0) -> 1
A32: Personal Care | B32: 240 | C32: =SUM(C14:E14) -> 225 | D32: =B32-C32 -> 15 | E32: =IFERROR(C32/B32,0) -> 0.9375
A33: Subscriptions | B33: 150 | C33: =SUM(C15:E15) -> 77.94 | D33: =B33-C33 -> 72.06 | E33: =IFERROR(C33/B33,0) -> 0.5196
A34: Savings | B34: 1800 | C34: =SUM(C16:E16) -> 1800 | D34: =B34-C34 -> 0 | E34: =IFERROR(C34/B34,0) -> 1
... A36: Other | B36: 300 | C36: =SUM(C18:E18) -> 217 | D36: =B36-C36 -> 83 | E36: =IFERROR(C36/B36,0) -> 0.72333333

Sheet RECURRING
A1: 🔄 RECURRING TRANSACTIONS — Subscriptions & Bills
A2: Track all fixed monthly costs. Annual cost auto-calculates. Active = Yes/No.
A3: # | B3: Description | C3: Category | D3: Amount | E3: Frequency | F3: Next Due | G3: Auto-Pay | H3: Active | I3: Annual Cost
A4: 1 | B4: Rent | C4: Housing | D4: 1500 | E4: Monthly | F4: 2025-02-01 | G4: No | H4: Yes | I4: =IF(H4="Yes",D4*12,0) -> 18000
A5: 2 | B5: Netflix | C5: Subscriptions | D5: 15.99 | E5: Monthly | F5: 2025-02-05 | G5: Yes | H5: Yes | I5: =IF(H5="Yes",D5*12,0) -> 191.88
A6: 3 | B6: Spotify | C6: Subscriptions | D6: 9.99 | E6: Monthly | F6: 2025-02-05 | G6: Yes | H6: Yes | I6: =IF(H6="Yes",D6*12,0) -> 119.88
A7: 4 | B7: Gym — Equinox | C7: Healthcare | D7: 40 | E7: Monthly | F7: 2025-02-01 | G7: Yes | H7: Yes | I7: =IF(H7="Yes",D7*12,0) -> 480
A8: 5 | B8: Car Insurance — Geico | C8: Insurance | D8: 120 | E8: Monthly | F8: 2025-02-15 | G8: Yes | H8: Yes | I8: =IF(H8="Yes",D8*12,0) -> 1440
A9: 6 | B9: Phone — Verizon | C9: Utilities | D9: 65 | E9: Monthly | F9: 2025-02-10 | G9: Yes | H9: Yes | I9: =IF(H9="Yes",D9*12,0) -> 780
A10: 7 | B10: Internet — Comcast | C10: Utilities | D10: 80 | E10: Monthly | F10: 2025-02-01 | G10: Yes | H10: Yes | I10: =IF(H10="Yes",D10*12,0) -> 960
A11: 8 | B11: Amazon Prime | C11: Subscriptions | D11: 14.99 | E11: Monthly | F11: 2025-02-14 | G11: Yes | H11: Yes | I11: =IF(H11="Yes",D11*12,0) -> 179.88
A12: 9 | B12: Adobe Creative Cloud | C12: Subscriptions | D12: 54.99 | E12: Monthly | F12: 2025-02-20 | G12: Yes | H12: Yes | I12: =IF(H12="Yes",D12*12,0) -> 659.88
A13: 10 | B13: Health Insurance | C13: Insurance | D13: 220 | E13: Monthly | F13: 2025-02-01 | G13: No | H13: Yes | I13: =IF(H13="Yes",D13*12,0) -> 2640
A14: 11 | B14: Electric Bill | C14: Utilities | D14: 95 | E14: Monthly | F14: 2025-02-10 | G14: No | H14: Yes | I14: =IF(H14="Yes",D14*12,0) -> 1140
A15: 12 | B15: Hulu | C15: Subscriptions | D15: 7.99 | E15: Monthly | F15: 2025-02-08 | G15: Yes | H15: Yes | I15: =IF(H15="Yes",D15*12,0) -> 95.88
A16: MONTHLY TOTAL (Active) | D16: =SUMIF(H4:H15,"Yes",D4:D15) -> 2223.95 | I16: =SUMIF(H4:H15,"Yes",I4:I15) -> 26687.4

Sheet WEALTH
A1: 💼 WEALTH BUILDING — Savings Goals · Debt Tracker
A3: 💰 SAVINGS GOALS TRACKER
A4: Goal Name | B4: Target ($) | C4: Saved ($) | D4: % Done | E4: Monthly $ | F4: Months Left | G4: Target Date | H4: Progress Bar
A5: Emergency Fund | B5: 10000 | C5: 7500 | D5: =IFERROR(C5/B5,0) -> 0.75 | E5: 500 | F5: =IFERROR(CEILING((B5-C5)/E5,1),0) -> 5 | G5: 2025-06-01 | H5: =REPT("█",ROUND(D5*10,0))&REPT("░",10-ROUND(D5*10,0)) -> ████████░░
A6: Europe Vacation | B6: 5000 | C6: 1200 | D6: =IFERROR(C6/B6,0) -> 0.24 | E6: 300 | F6: =IFERROR(CEILING((B6-C6)/E6,1),0) -> 13 | G6: 2025-09-01 | H6: =REPT("█",ROUND(D6*10,0))&REPT("░",10-ROUND(D6*10,0)) -> ██░░░░░░░░
A7: New MacBook Pro | B7: 3000 | C7: 1800 | D7: =IFERROR(C7/B7,0) -> 0.6 | E7: 250 | F7: =IFERROR(CEILING((B7-C7)/E7,1),0) -> 5 | G7: 2025-05-01 | H7: =REPT("█",ROUND(D7*10,0))&REPT("░",10-ROUND(D7*10,0)) -> ██████░░░░
A8: Down Payment Fund | B8: 50000 | C8: 12000 | D8: =IFERROR(C8/B8,0) -> 0.24 | E8: 1000 | F8: =IFERROR(CEILING((B8-C8)/E8,1),0) -> 38 | G8: 2027-01-01 | H8: =REPT("█",ROUND(D8*10,0))&REPT("░",10-ROUND(D8*10,0)) -> ██░░░░░░░░
A9: Wedding Fund | B9: 15000 | C9: 4500 | D9: =IFERROR(C9/B9,0) -> 0.3 | E9: 600 | F9: =IFERROR(CEILING((B9-C9)/E9,1),0) -> 18 | G9: 2026-06-01 | H9: =REPT("█",ROUND(D9*10,0))&REPT("░",10-ROUND(D9*10,0)) -> ███░░░░░░░
A12: 💳 DEBT PAYOFF TRACKER
A13: Debt Name | B13: Original Balance | C13: Current Balance | D13: Interest Rate | E13: Min Payment | F13: Extra Pmt | G13: Monthly Total | H13: Payoff Est.
A14: Citi Credit Card | B14: 3000 | C14: 1250 | D14: 0.2199 | E14: 35 | F14: 100 | G14: =E14+F14 -> 135 | H14: =IFERROR(EDATE(TODAY(),CEILING(C14/(G14*(1+D14/12)),1)),"N/A") -> 46515
A15: Federal Student Loan | B15: 25000 | C15: 18000 | D15: 0.065 | E15: 180 | F15: 50 | G15: =E15+F15 -> 230 | H15: =IFERROR(EDATE(TODAY(),CEILING(C15/(G15*(1+D15/12)),1)),"N/A") -> 48587
A16: Auto Loan — Honda | B16: 15000 | C16: 8500 | D16: 0.049 | E16: 280 | F16: 0 | G16: =E16+F16 -> 280 | H16: =IFERROR(EDATE(TODAY(),CEILING(C16/(G16*(1+D16/12)),1)),"N/A") -> 47157
A17: TOTAL DEBT | C17: =SUM(C14:C16) -> 27750

Sheet INVESTMENTS
A1: 📈 INVESTMENT PORTFOLIO — Holdings & Compound Growth Forecast
A2: Update Current Price to refresh all gain/loss and portfolio % calculations.
A3: Ticker | B3: Type | C3: Shares | D3: Buy Price | E3: Current Price | F3: Current Value | G3: Gain/Loss | H3: % Return | I3: Portfolio %
A4: AAPL | B4: Stock | C4: 10 | D4: 145 | E4: 182.5 | F4: =C4*E4 -> 1825 | G4: =(E4-D4)*C4 -> 375 | H4: =IFERROR((E4-D4)/D4,0) -> 0.25862069 | I4: =IFERROR(F4/SUM(F4:F9),0) -> 0.1777886
A5: VOO | B5: ETF | C5: 5 | D5: 380 | E5: 425 | F5: =C5*E5 -> 2125 | G5: =(E5-D5)*C5 -> 225 | H5: =IFERROR((E5-D5)/D5,0) -> 0.11842105 | I5: =IFERROR(F5/SUM(F4:F9),0) -> 0.20701413
A6: BND | B6: ETF | C6: 20 | D6: 72 | E6: 74.5 | F6: =C6*E6 -> 1490 | G6: =(E6-D6)*C6 -> 50 | H6: =IFERROR((E6-D6)/D6,0) -> 0.034722222 | I6: =IFERROR(F6/SUM(F4:F9),0) -> 0.14515343
A7: MSFT | B7: Stock | C7: 8 | D7: 250 | E7: 380 | F7: =C7*E7 -> 3040 | G7: =(E7-D7)*C7 -> 1040 | H7: =IFERROR((E7-D7)/D7,0) -> 0.52 | I7: =IFERROR(F7/SUM(F4:F9),0) -> 0.29615197
A8: GOOGL | B8: Stock | C8: 3 | D8: 120 | E8: 155 | F8: =C8*E8 -> 465 | G8: =(E8-D8)*C8 -> 105 | H8: =IFERROR((E8-D8)/D8,0) -> 0.29166667 | I8: =IFERROR(F8/SUM(F4:F9),0) -> 0.045299562
A9: VNQ | B9: ETF | C9: 15 | D9: 82 | E9: 88 | F9: =C9*E9 -> 1320 | G9: =(E9-D9)*C9 -> 90 | H9: =IFERROR((E9-D9)/D9,0) -> 0.073170732 | I9: =IFERROR(F9/SUM(F4:F9),0) -> 0.1285923
A10: PORTFOLIO TOTAL | F10: =SUM(F4:F9) -> 10265 | G10: =SUM(G4:G9) -> 1885
A12: 🔮 COMPOUND GROWTH FORECAST (10-Year Projection)
A13: Current Portfolio Value | C13: =F10 -> 10265
A14: Monthly Contribution ($) | C14: 500
A15: Annual Return Rate (%) | C15: 0.07
A17: Year | B17: Conservative (5%) | C17: Base Case (7%) | D17: Aggressive (10%)
A18: Year 1 | B18: =FV(0.05/12,1*12,-C14,-C13) -> 16929.605 | C18: =FV(0.07/12,1*12,-C14,-C13) -> 17203.35 | D18: =FV(0.1/12,1*12,-C14,-C13) -> 17622.664
A19: Year 2 | B19: =FV(0.05/12,2*12,-C14,-C13) -> 23935.183 | C19: =FV(0.07/12,2*12,-C14,-C13) -> 24643.275 | D19: =FV(0.1/12,2*12,-C14,-C13) -> 25750.771
A20: Year 3 | B20: =FV(0.05/12,3*12,-C14,-C13) -> 31299.18 | C20: =FV(0.07/12,3*12,-C14,-C13) -> 32621.032 | D20: =FV(0.1/12,3*12,-C14,-C13) -> 34729.997
A21: Year 4 | B21: =FV(0.05/12,4*12,-C14,-C13) -> 39039.933 | C21: =FV(0.07/12,4*12,-C14,-C13) -> 41175.501 | D21: =FV(0.1/12,4*12,-C14,-C13) -> 44649.466
A22: Year 5 | B22: =FV(0.05/12,5*12,-C14,-C13) -> 47176.718 | C22: =FV(0.07/12,5*12,-C14,-C13) -> 50348.374 | D22: =FV(0.1/12,5*12,-C14,-C13) -> 55607.632
A23: Year 6 | B23: =FV(0.05/12,6*12,-C14,-C13) -> 55729.796 | C23: =FV(0.07/12,6*12,-C14,-C13) -> 60184.355 | D23: =FV(0.1/12,6*12,-C14,-C13) -> 67713.262
A24: Year 7 | B24: =FV(0.05/12,7*12,-C14,-C13) -> 64720.466 | C24: =FV(0.07/12,7*12,-C14,-C13) -> 70731.379 | D24: =FV(0.1/12,7*12,-C14,-C13) -> 81086.51
A25: Year 8 | B25: =FV(0.05/12,8*12,-C14,-C13) -> 74171.116 | C25: =FV(0.07/12,8*12,-C14,-C13) -> 82040.849 | D25: =FV(0.1/12,8*12,-C14,-C13) -> 95860.111
A26: Year 9 | B26: =FV(0.05/12,9*12,-C14,-C13) -> 84105.279 | C26: =FV(0.07/12,9*12,-C14,-C13) -> 94167.881 | D26: =FV(0.1/12,9*12,-C14,-C13) -> 112180.7
A27: Year 10 | B27: =FV(0.05/12,10*12,-C14,-C13) -> 94547.692 | C27: =FV(0.07/12,10*12,-C14,-C13) -> 107171.58 | D27: =FV(0.1/12,10*12,-C14,-C13) -> 130210.27

Sheet NET WORTH
A1: 💰 NET WORTH TRACKER — Assets · Liabilities · Historical Trend
A3: 🏦 ASSETS & LIABILITIES SNAPSHOT
A4: Item | B4: Category | C4: Value ($) | D4: Type
A5: Chase Checking | B5: Cash | C5: 3250 | D5: Asset
A6: Marcus HYSA | B6: Cash | C6: 12500 | D6: Asset
A7: Fidelity Investment | B7: Investments | C7: 28000 | D7: Asset
A8: Roth IRA | B8: Retirement | C8: 15000 | D8: Asset
A9: Honda Civic (KBB) | B9: Vehicle | C9: 12000 | D9: Asset
A10: Personal Property | B10: Other | C10: 2500 | D10: Asset
A11: Citi Credit Card | B11: Credit Card | C11: -1250 | D11: Liability
A12: Student Loan | B12: Student Loan | C12: -18000 | D12: Liability
A13: Auto Loan | B13: Auto Loan | C13: -8500 | D13: Liability
A14: TOTAL ASSETS | C14: =SUMIF(D5:D13,"Asset",C5:C13) -> 73250
A15: TOTAL LIABILITIES | C15: =SUMIF(D5:D13,"Liability",C5:C13) -> -27750
A16: NET WORTH | C16: =C14+C15 -> 45500
A18: 📈 NET WORTH HISTORY
A19: Month | B19: Total Assets | C19: Total Liabilities | D19: Net Worth | E19: MoM Change
A20: Jan 2025 | B20: 71750 | C20: 27750 | D20: =B20+C20 -> 99500 | E20: —
A21: Feb 2025 | B21: 72500 | C21: 27500 | D21: =B21+C21 -> 100000 | E21: =D21-D20 -> 500
A22: Mar 2025 | B22: 73800 | C22: 27200 | D22: =B22+C22 -> 101000 | E22: =D22-D21 -> 1000
A23: Apr 2025 | B23: 75200 | C23: 26800 | D23: =B23+C23 -> 102000 | E23: =D23-D22 -> 1000
A24: May 2025 | B24: 76900 | C24: 26400 | D24: =B24+C24 -> 103300 | E24: =D24-D23 -> 1300
A25: Jun 2025 | B25: 78500 | C25: 26000 | D25: =B25+C25 -> 104500 | E25: =D25-D24 -> 1200

Sheet GOALS
A1: 🎯 GOAL MANAGEMENT SYSTEM — Track Goals to Completion
A2: Category and Status use dropdowns. Update Progress % regularly for accurate dashboard.
A4: # | B4: Goal Title | C4: Category | D4: Start Date | E4: Target Date | F4: Progress % | G4: Status | H4: Milestones / Notes
A5: 1 | B5: Build $10K Emergency Fund | C5: Financial | D5: 2025-01-01 | E5: 2025-06-01 | F5: 0.75 | G5: In Progress | H5: 1.$3K ✓ 2.$6K ✓ 3.$10K target
A6: 2 | B6: Run First 5K Race | C6: Health & Fitness | D6: 2025-01-01 | E6: 2025-04-15 | F6: 0.6 | G6: In Progress | H6: Training 3x/week — 4K best so far
A7: 3 | B7: Read 24 Books in 2025 | C7: Personal Development | D7: 2025-01-01 | E7: 2025-12-31 | F7: 0.25 | G7: In Progress | H7: 6/24 complete — on pace
A8: 4 | B8: Pass AWS Solutions Architect | C8: Career | D8: 2025-01-15 | E8: 2025-05-30 | F8: 0.4 | G8: In Progress | H8: Modules 4/10 — mock exams soon
A9: 5 | B9: Learn Conversational Spanish | C9: Education | D9: 2025-01-01 | E9: 2025-12-31 | F9: 0.15 | G9: In Progress | H9: Duolingo 62-day streak
A10: 6 | B10: Launch Freelance Design Studio | C10: Career | D10: 2025-02-01 | E10: 2025-08-01 | F10: 0.35 | G10: In Progress | H10: Portfolio done — 1st client pending
A11: 7 | B11: Trip to Japan | C11: Travel | D11: 2025-01-01 | E11: 2025-10-15 | F11: 0.55 | G11: In Progress | H11: Flights & hotels booked
A12: 8 | B12: Lose 15 lbs | C12: Health & Fitness | D12: 2025-01-01 | E12: 2025-07-01 | F12: 0.47 | G12: In Progress | H12: 7 lbs lost — gym 4x/week
A13: 9 | B13: Pay Off Citi Credit Card | C13: Financial | D13: 2025-01-01 | E13: 2025-09-01 | F13: 0.58 | G13: In Progress | H13: $1,250 remaining of $3,000
A14: 10 | B14: 30-Day Meditation Streak | C14: Personal Development | D14: 2025-03-01 | E14: 2025-03-31 | F14: 1 | G14: Completed | H14: 30/30 days ✓
A15: 11 | B15: Max Out Roth IRA 2025 | C15: Financial | D15: 2025-01-01 | E15: 2025-12-31 | F15: 0.3 | G15: In Progress | H15: $2,100 / $7,000 contributed
A16: 12 | B16: Finish Online Coding Bootcamp | C16: Education | D16: 2025-02-01 | E16: 2025-07-01 | F16: 0.45 | G16: In Progress | H16: Module 9/20 complete

Sheet HABITS
A1: ✅ DAILY HABIT TRACKER — January 2025 | 15 Habits × 31 Days
A2: Enter ✓ for each completed habit. Completion % and Streak auto-calculate at the right.
C3: HABIT | D3: 1 | E3: 2 | F3: 3 | G3: 4 | H3: 5 | I3: 6 | J3: 7 | K3: 8 | L3: 9 | M3: 10 | N3: 11 | O3: 12 | P3: 13 | Q3: 14 | R3: 15 | S3: 16 | T3: 17 | U3: 18 | V3: 19 | W3: 20 | X3: 21 | Y3: 22 | Z3: 23 | AA3: 24 | AB3: 25 | AC3: 26 | AD3: 27 | AE3: 28 | AF3: 29 | AG3: 30 | AH3: 31 | AJ3: Done✓ | AK3: Rate | AL3: Streak🔥
C4: Morning Meditation 🧘 | D4: ✓ | E4: ✓ | G4: ✓ | H4: ✓ | I4: ✓ | K4: ✓ | L4: ✓ | M4: ✓ | O4: ✓ | P4: ✓ | Q4: ✓ | S4: ✓ | T4: ✓ | U4: ✓ | W4: ✓ | X4: ✓ | Z4: ✓ | AA4: ✓ | AB4: ✓ | AD4: ✓ | AE4: ✓ | AF4: ✓ | AH4: ✓ | AJ4: 23 | AK4: 0.74193548 | AL4: 1d
C5: Exercise / Workout 🏋️ | D5: ✓ | E5: ✓ | F5: ✓ | H5: ✓ | I5: ✓ | J5: ✓ | K5: ✓ | M5: ✓ | N5: ✓ | O5: ✓ | Q5: ✓ | R5: ✓ | S5: ✓ | T5: ✓ | V5: ✓ | W5: ✓ | Y5: ✓ | Z5: ✓ | AA5: ✓ | AB5: ✓ | AD5: ✓ | AE5: ✓ | AF5: ✓ | AH5: ✓ | AJ5: 24 | AK5: 0.77419355 | AL5: 1d
C6: Drink 8 Glasses Water 💧 | D6: ✓ | E6: ✓ | F6: ✓ | G6: ✓ | H6: ✓ | I6: ✓ | J6: ✓ | K6: ✓ | L6: ✓ | M6: ✓ | N6: ✓ | O6: ✓ | P6: ✓ | Q6: ✓ | R6: ✓ | S6: ✓ | T6: ✓ | U6: ✓ | V6: ✓ | W6: ✓ | X6: ✓ | Y6: ✓ | Z6: ✓ | AA6: ✓ | AB6: ✓ | AC6: ✓ | AD6: ✓ | AE6: ✓ | AF6: ✓ | AG6: ✓ | AH6: ✓ | AJ6: 31 | AK6: 1 | AL6: 31d
C7: Read 30 Minutes 📚 | E7: ✓ | G7: ✓ | I7: ✓ | J7: ✓ | L7: ✓ | N7: ✓ | O7: ✓ | Q7: ✓ | R7: ✓ | S7: ✓ | U7: ✓ | W7: ✓ | X7: ✓ | Z7: ✓ | AB7: ✓ | AC7: ✓ | AE7: ✓ | AF7: ✓ | AH7: ✓ | AJ7: 19 | AK7: 0.61290323 | AL7: 1d
C8: No Social Media Before 9AM 📵 | D8: ✓ | F8: ✓ | G8: ✓ | I8: ✓ | J8: ✓ | K8: ✓ | M8: ✓ | N8: ✓ | P8: ✓ | Q8: ✓ | S8: ✓ | T8: ✓ | V8: ✓ | W8: ✓ | X8: ✓ | Z8: ✓ | AA8: ✓ | AC8: ✓ | AD8: ✓ | AE8: ✓ | AG8: ✓ | AH8: ✓ | AJ8: 22 | AK8: 0.70967742 | AL8: 2d
C9: Healthy Breakfast 🥗 | D9: ✓ | E9: ✓ | F9: ✓ | H9: ✓ | J9: ✓ | K9: ✓ | L9: ✓ | N9: ✓ | O9: ✓ | P9: ✓ | R9: ✓ | T9: ✓ | U9: ✓ | V9: ✓ | X9: ✓ | Y9: ✓ | Z9: ✓ | AB9: ✓ | AD9: ✓ | AE9: ✓ | AF9: ✓ | AH9: ✓ | AJ9: 22 | AK9: 0.70967742 | AL9: 1d
C10: Evening Journal 📔 | F10: ✓ | G10: ✓ | I10: ✓ | L10: ✓ | M10: ✓ | O10: ✓ | R10: ✓ | S10: ✓ | U10: ✓ | X10: ✓ | Y10: ✓ | AA10: ✓ | AD10: ✓ | AE10: ✓ | AG10: ✓ | AJ10: 15 | AK10: 0.48387097 | AL10: 0d
C11: Sleep Before 11PM 🌙 | D11: ✓ | E11: ✓ | G11: ✓ | H11: ✓ | J11: ✓ | K11: ✓ | M11: ✓ | N11: ✓ | O11: ✓ | P11: ✓ | Q11: ✓ | S11: ✓ | T11: ✓ | V11: ✓ | W11: ✓ | Y11: ✓ | Z11: ✓ | AB11: ✓ | AC11: ✓ | AE11: ✓ | AF11: ✓ | AG11: ✓ | AH11: ✓ | AJ11: 23 | AK11: 0.74193548 | AL11: 4d
C12: Gratitude Practice 🙏 | D12: ✓ | E12: ✓ | F12: ✓ | G12: ✓ | J12: ✓ | K12: ✓ | L12: ✓ | M12: ✓ | P12: ✓ | Q12: ✓ | R12: ✓ | S12: ✓ | V12: ✓ | W12: ✓ | X12: ✓ | Y12: ✓ | AB12: ✓ | AC12: ✓ | AD12: ✓ | AE12: ✓ | AH12: ✓ | AJ12: 21 | AK12: 0.67741935 | AL12: 1d
C13: 10,000 Steps 🚶 | D13: ✓ | E13: ✓ | F13: ✓ | G13: ✓ | H13: ✓ | J13: ✓ | K13: ✓ | L13: ✓ | M13: ✓ | N13: ✓ | P13: ✓ | Q13: ✓ | R13: ✓ | S13: ✓ | T13: ✓ | V13: ✓ | W13: ✓ | X13: ✓ | Y13: ✓ | Z13: ✓ | AB13: ✓ | AC13: ✓ | AD13: ✓ | AE13: ✓ | AF13: ✓ | AH13: ✓ | AJ13: 26 | AK13: 0.83870968 | AL13: 1d
C14: Learn Something New 🎓 | D14: ✓ | E14: ✓ | F14: ✓ | H14: ✓ | I14: ✓ | J14: ✓ | L14: ✓ | M14: ✓ | N14: ✓ | P14: ✓ | Q14: ✓ | R14: ✓ | T14: ✓ | U14: ✓ | V14: ✓ | X14: ✓ | Y14: ✓ | Z14: ✓ | AB14: ✓ | AC14: ✓ | AD14: ✓ | AF14: ✓ | AG14: ✓ | AH14: ✓ | AJ14: 24 | AK14: 0.77419355 | AL14: 3d
C15: Review Goals 🎯 | D15: ✓ | F15: ✓ | G15: ✓ | H15: ✓ | J15: ✓ | K15: ✓ | L15: ✓ | N15: ✓ | O15: ✓ | P15: ✓ | R15: ✓ | S15: ✓ | T15: ✓ | V15: ✓ | W15: ✓ | X15: ✓ | Z15: ✓ | AA15: ✓ | AB15: ✓ | AD15: ✓ | AE15: ✓ | AF15: ✓ | AH15: ✓ | AJ15: 23 | AK15: 0.74193548 | AL15: 1d
C16: No Junk Food 🥦 | D16: ✓ | E16: ✓ | G16: ✓ | I16: ✓ | J16: ✓ | L16: ✓ | N16: ✓ | O16: ✓ | Q16: ✓ | S16: ✓ | T16: ✓ | V16: ✓ | X16: ✓ | Y16: ✓ | AA16: ✓ | AC16: ✓ | AD16: ✓ | AF16: ✓ | AH16: ✓ | AJ16: 19 | AK16: 0.61290323 | AL16: 1d
C17: Connect With a Friend 👥 | E17: ✓ | F17: ✓ | H17: ✓ | I17: ✓ | K17: ✓ | L17: ✓ | N17: ✓ | O17: ✓ | Q17: ✓ | R17: ✓ | T17: ✓ | U17: ✓ | W17: ✓ | X17: ✓ | Z17: ✓ | AA17: ✓ | AC17: ✓ | AD17: ✓ | AF17: ✓ | AG17: ✓ | AJ17: 20 | AK17: 0.64516129 | AL17: 0d
C18: Cold Shower 🚿 | E18: ✓ | H18: ✓ | K18: ✓ | N18: ✓ | Q18: ✓ | T18: ✓ | W18: ✓ | Z18: ✓ | AC18: ✓ | AF18: ✓ | AJ18: 10 | AK18: 0.32258065 | AL18: 0d
C19: Daily Total ✓ | D19: =COUNTIF(D4:D18,"✓") -> 11 | E19: =COUNTIF(E4:E18,"✓") -> 12 | F19: =COUNTIF(F4:F18,"✓") -> 10 | G19: =COUNTIF(G4:G18,"✓") -> 10 | H19: =COUNTIF(H4:H18,"✓") -> 10 | I19: =COUNTIF(I4:I18,"✓") -> 9 | J19: =COUNTIF(J4:J18,"✓") -> 11 | K19: =COUNTIF(K4:K18,"✓") -> 11 | ... AH19: =COUNTIF(AH4:AH18,"✓") -> 12

Sheet CALENDAR
B1: 🗓️ MONTHLY CALENDAR — January 2025
B3: SUN | C3: MON | D3: TUE | E3: WED | F3: THU | G3: FRI | H3: SAT
E4: 1 | F4: 2 | G4: 3 | H4: 4
G5: 👥 Team Standup
B8: 5 | C8: 6 | D8: 7 | E8: 8 | F8: 9 | G8: 10 | H8: 11
D9: 🏃 5K Race | G9: 💼 Client Meeting
B12: 12 | C12: 13 | D12: 14 | E12: 15 | F12: 16 | G12: 17 | H12: 18
E13: 🎂 Birthday Party
B16: 19 | C16: 20 | D16: 21 | E16: 22 | F16: 23 | G16: 24 | H16: 25
C17: ✈️ Trip Departs | E17: 🏥 Doctor Appt
B20: 26 | C20: 27 | D20: 28 | E20: 29 | F20: 30 | G20: 31
D21: 📊 Budget Review

Sheet WEEKLY PLAN
A1: ⏰ WEEKLY SCHEDULE — Week of Jan 13–19, 2025
A2: Color-coded by activity type. Edit any cell to update your schedule.
A3: TIME | B3: MON | C3: TUE | D3: WED | E3: THU | F3: FRI | G3: SAT | H3: SUN
A4: 6:00 AM | B4: Meditate | C4: Meditate | D4: Meditate | E4: Meditate | F4: Meditate
A5: 7:00 AM | B5: Workout | G5: Long Run | H5: Rest
A6: 8:00 AM | B6: Standup | C6: Standup | D6: Standup | E6: Standup | F6: Standup
A7: 9:00 AM | B7: Deep Work | C7: Deep Work | D7: Deep Work | E7: Deep Work | F7: Deep Work
A8: 10:00 AM
A9: 11:00 AM
A10: 12:00 PM | B10: Lunch | C10: Lunch | D10: Lunch | E10: Lunch | F10: Lunch | G10: Lunch
A11: 1:00 PM | B11: Meetings | D11: 1-on-1 | F11: Review
A12: 2:00 PM | G12: Grocery
A13: 3:00 PM
A14: 4:00 PM | H14: Games
A15: 5:00 PM | B15: Study | C15: Study | E15: Study | F15: Study
A16: 6:00 PM
A17: 7:00 PM | B17: Read | C17: Read | D17: Read | E17: Read | F17: Read
A18: 8:00 PM | G18: Meal Prep | H18: Family Time
A19: 9:00 PM

Sheet TASKS
A1: 📝 TASK MANAGEMENT — Full Task List with Priority & Status
A2: Priority and Status use dropdowns. Color coding: Red=Critical, Orange=High, Blue=Medium.
A4: # | B4: Task Title | C4: Due Date | D4: Priority | E4: Category | F4: Status | G4: Est.Hrs | H4: Done Hrs | I4: Project / Notes
A5: 1 | B5: Complete Q1 Financial Review | C5: 2025-01-20 | D5: Critical | E5: Finance | F5: In Progress | G5: 2 | H5: 1.5 | I5: Finance Review
A6: 2 | B6: Submit AWS Certification Application | C6: 2025-01-25 | D6: High | E6: Career | F6: Not Started | G6: 1 | H6: 0 | I6: Need ID scan
A7: 3 | B7: Prepare Monthly Budget | C7: 2025-01-31 | D7: Critical | E7: Finance | F7: In Progress | G7: 1.5 | H7: 0.5 | I7: Jan update
A8: 4 | B8: Write Blog Post — Productivity Tips | C8: 2025-02-01 | D8: Medium | E8: Personal | F8: Not Started | G8: 3 | H8: 0 | I8: Outline done
A9: 5 | B9: Organize Home Office | C9: 2025-01-21 | D9: Medium | E9: Home | F9: Not Started | G9: 2 | H9: 0
A10: 6 | B10: Research High-Yield Savings | C10: 2025-01-22 | D10: High | E10: Finance | F10: Completed | G10: 1 | H10: 1 | I10: Done ✓
A11: 7 | B11: Update Resume and LinkedIn | C11: 2025-02-05 | D11: High | E11: Career | F11: Not Started | G11: 2 | H11: 0
A12: 8 | B12: Plan Japan Trip Itinerary | C12: 2025-02-15 | D12: Medium | E12: Personal | F12: In Progress | G12: 4 | H12: 2 | I12: Hotels TBD
A13: 9 | B13: Read Atomic Habits Ch 5–10 | C13: 2025-01-19 | D13: Medium | E13: Learning | F13: In Progress | G13: 3 | H13: 1
A14: 10 | B14: Schedule Annual Physical | C14: 2025-01-18 | D14: High | E14: Health | F14: Completed | G14: 0.5 | H14: 0.5 | I14: Booked Jan 22
A15: 11 | B15: Finish React Native Course | C15: 2025-02-28 | D15: Medium | E15: Learning | F15: In Progress | G15: 20 | H15: 8 | I15: Module 6/12
A16: 12 | B16: Weekly Call with Family | C16: 2025-01-18 | D16: High | E16: Social | F16: Completed | G16: 1 | H16: 1 | I16: Every Sunday
A17: 13 | B17: Sunday Meal Prep | C17: 2025-01-19 | D17: Medium | E17: Health | F17: Not Started | G17: 2 | H17: 0
A18: 14 | B18: Review & Update Goals | C18: 2025-01-31 | D18: High | E18: Personal | F18: Not Started | G18: 1 | H18: 0 | I18: Monthly review
A19: 15 | B19: Fix Production Bug #247 | C19: 2025-01-17 | D19: Critical | E19: Work | F19: Completed | G19: 3 | H19: 3.5 | I19: Deployed ✓
A20: 16 | B20: Interview Prep — Mock Questions | C20: 2025-02-10 | D20: High | E20: Career | F20: Not Started | G20: 4 | H20: 0
A21: 17 | B21: File Q4 Taxes | C21: 2025-04-15 | D21: Critical | E21: Finance | F21: Not Started | G21: 3 | H21: 0 | I21: Get CPA docs
A22: 18 | B22: Finalize Side Project MVP | C22: 2025-03-01 | D22: High | E22: Work | F22: In Progress | G22: 30 | H22: 12 | I22: Beta launch
A23: 19 | B23: Deep Clean Apartment | C23: 2025-01-25 | D23: Low | E23: Home | F23: Not Started | G23: 3 | H23: 0
A24: 20 | B24: Buy Birthday Gift for Mom | C24: 2025-01-28 | D24: High | E24: Social | F24: Not Started | G24: 0.5 | H24: 0 | I24: Feb 2nd
A25: 📊 TASK SUMMARY BY STATUS
A26: Status | C26: Count | D26: % of Total
A27: Not Started | C27: =COUNTIF(F5:F24,A27) -> 10 | D27: =IFERROR(C27/SUM(C27:C31),0) -> 0.5
A28: In Progress | C28: =COUNTIF(F5:F24,A28) -> 6 | D28: =IFERROR(C28/SUM(C27:C31),0) -> 0.3
A29: Completed | C29: =COUNTIF(F5:F24,A29) -> 4 | D29: =IFERROR(C29/SUM(C27:C31),0) -> 0.2
A30: On Hold | C30: =COUNTIF(F5:F24,A30) -> 0 | D30: =IFERROR(C30/SUM(C27:C31),0) -> 0
A31: Cancelled | C31: =COUNTIF(F5:F24,A31) -> 0 | D31: =IFERROR(C31/SUM(C27:C31),0) -> 0

Sheet PRIORITY
A1: ⚡ PRIORITY MATRIX — Eisenhower Matrix + Kanban Board
A3: ⚡ EISENHOWER DECISION MATRIX
A4: 🔴 DO FIRST (Urgent + Important) | I4: 🟢 SCHEDULE (Important, Not Urgent)
A5: • Fix production bug | I5: • Exercise routine
A6: • Tax filing deadline | I6: • Deep work projects
A7: • Emergency fund gap | I7: • AWS certification
A8: • Doctor appointment | I8: • Japan trip planning
A9: • Client pres. tomorrow | I9: • Financial goals
A13: 🟡 DELEGATE (Urgent, Not Important) | I13: ⚪ ELIMINATE (Not Urgent, Not Important)
A14: • Some emails/calls | I14: • Browsing social media
A15: • Routine admin tasks | I15: • Random YouTube
A16: • Optional meetings | I16: • Low-value meetings
A17: • Document formatting | I17: • Excessive email
A18: • Status updates | I18: • Busy-work
A22: 📌 KANBAN BOARD
A23: 📥 BACKLOG | E23: 📋 TO DO | I23: ⚡ IN PROGRESS | M23: ✅ DONE
A24: Research competitors | E24: Budget weekly review | I24: Fix login bug | M24: Emergency fund setup
A25: Update portfolio | E25: Apply AWS cert | I25: Project proposal | M25: Q1 budget plan
A26: 3 blog posts | E26: Update resume | I26: Japan trip plan | M26: Finished: Deep Work
A27: Setup automations | E27: Read Atomic Habits | I27: Side project MVP | M27: 5K race registered
A28: Redesign landing page | E28: Plan Q2 goals | I28: AWS course mod 6 | M28: Monthly review done

Sheet HEALTH
A1: 🏃 HEALTH & WELLNESS TRACKER — Weight · Exercise · Sleep · Mood
A2: Log daily. All charts auto-generate. Mood scale: 1 (Terrible) to 10 (Excellent).
A4: # | B4: Date | C4: Weight(lbs) | D4: Body Fat% | E4: Exercise Type | F4: Duration(min) | G4: Water(glasses) | H4: Sleep(hrs) | I4: Mood(1-10) | J4: Calories | K4: Notes
A5: 1 | B5: 2025-01-01 | C5: 185.2 | D5: 18.5 | E5: Rest Day | F5: 0 | G5: 7 | H5: 7.5 | I5: 7 | J5: 1850 | K5: New Year
A6: 2 | B6: 2025-01-02 | C6: 185 | D6: 18.4 | E6: Chest & Triceps | F6: 55 | G6: 8 | H6: 7 | I6: 8 | J6: 2100 | K6: Good pump
A7: 3 | B7: 2025-01-03 | C7: 184.8 | D7: 18.3 | E7: Run 3K | F7: 30 | G7: 9 | H7: 8 | I7: 9 | J7: 1950
A8: 4 | B8: 2025-01-04 | C8: 184.5 | D8: 18.2 | E8: Back & Biceps | F8: 60 | G8: 8 | H8: 6.5 | I8: 7 | J8: 2200 | K8: Tired
A9: 5 | B9: 2025-01-05 | C9: 184.2 | D9: 18.1 | E9: Rest Day | F9: 0 | G9: 6 | H9: 9 | I9: 8 | J9: 1800
A10: 6 | B10: 2025-01-06 | C10: 184 | D10: 18 | E10: Yoga | F10: 45 | G10: 8 | H10: 7.5 | I10: 9 | J10: 1750
A11: 7 | B11: 2025-01-07 | C11: 183.8 | D11: 17.9 | E11: Leg Day | F11: 65 | G11: 9 | H11: 7 | I11: 8 | J11: 2300 | K11: Squats PR
A12: 8 | B12: 2025-01-08 | C12: 183.5 | D12: 17.8 | E12: Run 4K | F12: 35 | G12: 8 | H12: 8 | I12: 8 | J12: 2000
A13: 9 | B13: 2025-01-09 | C13: 183.2 | D13: 17.7 | E13: Shoulders | F13: 55 | G13: 9 | H13: 7.5 | I13: 9 | J13: 2100
A14: 10 | B14: 2025-01-10 | C14: 183 | D14: 17.6 | E14: HIIT | F14: 40 | G14: 7 | H14: 6 | I14: 6 | J14: 2400 | K14: Stressful day
A15: 11 | B15: 2025-01-11 | C15: 183.2 | D15: 17.7 | E15: Rest Day | F15: 0 | G15: 8 | H15: 8.5 | I15: 8 | J15: 1900
A16: 12 | B16: 2025-01-12 | C16: 182.8 | D16: 17.5 | E16: Run 5K | F16: 45 | G16: 9 | H16: 8 | I16: 9 | J16: 2050 | K16: New PR!
A17: 13 | B17: 2025-01-13 | C17: 182.5 | D17: 17.4 | E17: Full Body | F17: 70 | G17: 8 | H17: 7 | I17: 8 | J17: 2200
A18: 14 | B18: 2025-01-14 | C18: 182.2 | D18: 17.3 | E18: Walk | F18: 30 | G18: 7 | H18: 8.5 | I18: 8 | J18: 1850
A19: 15 | B19: 2025-01-15 | C19: 182 | D19: 17.2 | E19: Chest & Triceps | F19: 55 | G19: 9 | H19: 7 | I19: 8 | J19: 2100
A20: 16 | B20: 2025-01-16 | C20: 181.8 | D20: 17.1 | E20: Run 5K | F20: 48 | G20: 9 | H20: 8 | I20: 9 | J20: 2000
A21: 17 | B21: 2025-01-17 | C21: 181.5 | D21: 17 | E21: Rest Day | F21: 0 | G21: 7 | H21: 9 | I21: 8 | J21: 1800
A22: 18 | B22: 2025-01-18 | C22: 181.2 | D22: 16.9 | E22: Yoga | F22: 45 | G22: 8 | H22: 8 | I22: 9 | J22: 1750 | K22: Feeling great
A23: 19 | B23: 2025-01-19 | C23: 181 | D23: 16.8 | E23: Leg Day | F23: 65 | G23: 9 | H23: 7 | I23: 8 | J23: 2300
A24: 20 | B24: 2025-01-20 | C24: 180.8 | D24: 16.7 | E24: Run 6K | F24: 52 | G24: 9 | H24: 8.5 | I24: 9 | J24: 2050 | K24: Long run done
A25: 📊 HEALTH SUMMARY STATS
A26: Metric | C26: Average | D26: Min | E26: Max
A27: Weight (lbs) | C27: =AVERAGE(C5:C24) -> 183.01 | D27: =MIN(C5:C24) -> 180.8 | E27: =MAX(C5:C24) -> 185.2
A28: Exercise (min) | C28: =AVERAGE(F5:F24) -> 39.75 | D28: =MIN(F5:F24) -> 0 | E28: =MAX(F5:F24) -> 70
A29: Water (glasses) | C29: =AVERAGE(G5:G24) -> 8.1 | D29: =MIN(G5:G24) -> 6 | E29: =MAX(G5:G24) -> 9
A30: Sleep (hrs) | C30: =AVERAGE(H5:H24) -> 7.675 | D30: =MIN(H5:H24) -> 6 | E30: =MAX(H5:H24) -> 9
A31: Mood (1-10) | C31: =AVERAGE(I5:I24) -> 8.15 | D31: =MIN(I5:I24) -> 6 | E31: =MAX(I5:I24) -> 9

Sheet MEALS
A1: 🍽️ MEAL PLANNING SYSTEM — Database · Weekly Plan · Grocery List
A3: 📚 MEAL DATABASE
A4: Meal Name | B4: Category | C4: Calories | D4: Protein(g) | E4: Carbs(g) | F4: Fat(g) | G4: Prep(min) | H4: Notes
A5: Overnight Oats | B5: Breakfast | C5: 380 | D5: 15 | E5: 62 | F5: 8 | G5: 5 | H5: Oats, almond milk, banana, honey
A6: Eggs & Avocado Toast | B6: Breakfast | C6: 420 | D6: 18 | E6: 35 | F6: 22 | G6: 10 | H6: Sourdough, 2 eggs, 1/2 avocado
A7: Greek Yogurt Parfait | B7: Breakfast | C7: 290 | D7: 22 | E7: 38 | F7: 5 | G7: 3 | H7: Greek yogurt, berries, granola
A8: Protein Smoothie | B8: Breakfast | C8: 310 | D8: 30 | E8: 28 | F8: 8 | G8: 5 | H8: Whey, banana, almond milk, PB
A9: Grilled Chicken Salad | B9: Lunch | C9: 450 | D9: 42 | E9: 20 | F9: 18 | G9: 15 | H9: Chicken, mixed greens, vinaigrette
A10: Turkey Quinoa Bowl | B10: Lunch | C10: 520 | D10: 38 | E10: 55 | F10: 12 | G10: 20 | H10: Ground turkey, quinoa, roasted veg
A11: Tuna Sandwich | B11: Lunch | C11: 380 | D11: 30 | E11: 40 | F11: 10 | G11: 5 | H11: Tuna, whole wheat, lettuce, tomato
A12: Salmon & Vegetables | B12: Dinner | C12: 550 | D12: 45 | E12: 30 | F12: 22 | G12: 25 | H12: Salmon, broccoli, sweet potato
A13: Beef & Rice Bowl | B13: Dinner | C13: 620 | D13: 45 | E13: 55 | F13: 18 | G13: 30 | H13: Lean beef, rice, mixed vegetables
A14: Baked Chicken Thighs | B14: Dinner | C14: 480 | D14: 46 | E14: 12 | F14: 24 | G14: 40 | H14: Chicken, herbs, roasted potatoes
A15: Pasta Bolognese | B15: Dinner | C15: 580 | D15: 35 | E15: 68 | F15: 15 | G15: 35 | H15: Lean ground beef, whole wheat pasta
A16: Apple & Almond Butter | B16: Snack | C16: 195 | D16: 5 | E16: 22 | F16: 12 | G16: 2 | H16: 1 apple, 2 tbsp almond butter
... A19: Overnight Oats Variation | B19: Breakfast | C19: 360 | D19: 14 | E19: 58 | F19: 9 | G19: 5 | H19: Oats, protein powder, berries
A22: 📅 WEEKLY MEAL PLANNER
A23: MEAL | B23: MON | C23: TUE | D23: WED | E23: THU | F23: FRI | G23: SAT | H23: SUN
A24: Breakfast | B24: Overnight Oats | C24: Eggs & Avocado | D24: Greek Yogurt | E24: Overnight Oats | F24: Protein Smoothie | G24: Eggs & Avocado | H24: Greek Yogurt
A25: Lunch | B25: Chicken Salad | C25: Turkey Quinoa | D25: Tuna Sandwich | E25: Chicken Salad | F25: Quinoa Bowl | G25: Turkey Quinoa | H25: Tuna Sandwich
A26: Dinner | B26: Salmon & Veg | C26: Beef & Rice | D26: Baked Chicken | E26: Pasta Bolo | F26: Salmon & Veg | G26: Beef & Rice | H26: Baked Chicken
A27: Snack | B27: Apple & AB | C27: Protein Bar | D27: Hummus & Veg | E27: Apple & AB | F27: Protein Bar | G27: Hummus & Veg | H27: Apple & AB
A29: 🛒 WEEKLY GROCERY LIST
A30: Item | B30: Category | C30: Qty | D30: Unit | E30: Est. Cost | F30: In Stock? | G30: Notes
A31: Chicken Breast | B31: Protein | C31: 2 | D31: lbs | E31: 8.99 | F31: No
A32: Salmon Fillets | B32: Protein | C32: 1 | D32: lbs | E32: 12.99 | F32: No
A33: Ground Beef | B33: Protein | C33: 1.5 | D33: lbs | E33: 9.99 | F33: No
A34: Eggs | B34: Protein | C34: 12 | D34: count | E34: 4.99 | F34: Yes
A35: Greek Yogurt | B35: Dairy | C35: 2 | D35: cups | E35: 3.99 | F35: No | G35: Full fat
A36: Rolled Oats | B36: Grains | C36: 1 | D36: bag | E36: 3.49 | F36: Yes
A37: Quinoa | B37: Grains | C37: 1 | D37: bag | E37: 6.99 | F37: No
A38: Whole Wheat Bread | B38: Grains | C38: 1 | D38: loaf | E38: 3.99 | F38: No
A39: Mixed Greens | B39: Produce | C39: 1 | D39: bag | E39: 4.99 | F39: No
A40: Broccoli | B40: Produce | C40: 2 | D40: heads | E40: 2.99 | F40: No
A41: Sweet Potato | B41: Produce | C41: 3 | D41: count | E41: 1.99 | F41: No
A42: Avocado | B42: Produce | C42: 3 | D42: count | E42: 1.49 | F42: No
A43: Bananas | B43: Produce | C43: 1 | D43: bunch | E43: 1.29 | F43: No
A44: Almond Butter | B44: Pantry | C44: 1 | D44: jar | E44: 8.99 | F44: Yes
A45: Whey Protein | B45: Supplement | C45: 1 | D45: tub | E45: 34.99 | F45: No
A46: ESTIMATED TOTAL | E46: =SUM(E31:E45) -> 112.15

Sheet ANALYTICS
A1: 📊 PRODUCTIVITY ANALYTICS — 6-Month Performance Trends
A2: Live KPIs pull from all sheets. Trend data shows 6-month historical performance.
A4: 🏆 LIVE PERFORMANCE METRICS
A5: Metric | B5: Live Value | C5: Target | D5: Status | E5: Gap
A6: Habit Completion Rate | B6: =IFERROR(COUNTIF(HABITS!D4:AH18,"✓")/(15*31),0) -> 0.69247312 | C6: 0.8 | D6: =IF(B6>=C6,"✅ On Target","⚠️ Below") -> ⚠️ Below | E6: =IFERROR(B6-C6,0) -> -0.10752688
A7: Avg Goal Progress | B7: =IFERROR(AVERAGE(GOALS!F5:F16),0) -> 0.4875 | C7: 0.7 | D7: =IF(B7>=C7,"✅ On Target","⚠️ Below") -> ⚠️ Below | E7: =IFERROR(B7-C7,0) -> -0.2125
A8: Task Completion Rate | B8: =IFERROR(COUNTIF(TASKS!F5:F24,"Completed")/COUNTA(TASKS!F5:F24),0) -> 0.2 | C8: 0.5 | D8: =IF(B8>=C8,"✅ On Target","⚠️ Below") -> ⚠️ Below | E8: =IFERROR(B8-C8,0) -> -0.3
A9: Monthly Savings Rate | B9: =IFERROR((SUM(INCOME!E4:E18)-SUM(EXPENSES!D4:D28))/SUM(INCOME!E4:E18),0) -> 0.80307168 | C9: 0.2 | D9: =IF(B9>=C9,"✅ On Target","⚠️ Below") -> ✅ On Target | E9: =IFERROR(B9-C9,0) -> 0.60307168
A10: Budget Adherence | B10: =IFERROR(1-SUMIF(BUDGET!G5:G18,"⚠️ Over Budget",BUDGET!F5:F18)/SUM(BUDGET!F5:F18),0.88) -> 0.94154588 | C10: 0.9 | D10: =IF(B10>=C10,"✅ On Target","⚠️ Below") -> ✅ On Target | E10: =IFERROR(B10-C10,0) -> 0.041545882
A11: Avg Daily Mood | B11: =IFERROR(AVERAGE(HEALTH!I5:I24),0) -> 8.15 | C11: 8 | D11: =IF(B11>=C11,"✅ On Target","⚠️ Below") -> ✅ On Target | E11: =IFERROR(B11-C11,0) -> 0.15
A12: Avg Daily Sleep (hrs) | B12: =IFERROR(AVERAGE(HEALTH!H5:H24),0) -> 7.675 | C12: 8 | D12: =IF(B12>=C12,"✅ On Target","⚠️ Below") -> ⚠️ Below | E12: =IFERROR(B12-C12,0) -> -0.325
A13: Exercise Days (Month) | B13: =IFERROR(COUNTIF(HEALTH!F5:F24,">0"),0) -> 16 | C13: 20 | D13: =IF(B13>=C13,"✅ On Target","⚠️ Below") -> ⚠️ Below | E13: =IFERROR(B13-C13,0) -> -4
A16: 📈 6-MONTH PERFORMANCE TRENDS
A17: Month | B17: Habit Rate | C17: Goal Progress | D17: Task Rate | E17: Savings Rate | F17: Mood Avg | G17: Budget Score
A18: Jan 2025 | B18: 0.72 | C18: 0.45 | D18: 0.4 | E18: 0.18 | F18: 7.8 | G18: 0.91
A19: Feb 2025 | B19: 0.75 | C19: 0.52 | D19: 0.45 | E19: 0.2 | F19: 7.5 | G19: 0.88
A20: Mar 2025 | B20: 0.78 | C20: 0.58 | D20: 0.5 | E20: 0.22 | F20: 8 | G20: 0.92
A21: Apr 2025 | B21: 0.8 | C21: 0.63 | D21: 0.55 | E21: 0.21 | F21: 7.9 | G21: 0.89
A22: May 2025 | B22: 0.82 | C22: 0.68 | D22: 0.6 | E22: 0.23 | F22: 8.2 | G22: 0.93
A23: Jun 2025 | B23: 0.79 | C23: 0.72 | D23: 0.65 | E23: 0.25 | F23: 8.1 | G23: 0.9

Sheet USER GUIDE
A1: 📖 USER GUIDE — How to Use This Workbook
A3: GETTING STARTED
C4: Step 1 | D4: Open the 🔐 START tab and type life2025 in the yellow cell to verify access.
C5: Step 2 | D5: Go to ⚙️ SETUP to customise all category lists that power every dropdown.
C6: Step 3 | D6: Enter your bank accounts, income, and initial expenses to populate the dashboard.
C7: Step 4 | D7: Set your goals in 🎯 GOALS and habits in ✅ HABITS with progress % each week.
C8: Step 5 | D8: Use 📝 TASKS daily; Priority & Status dropdowns keep everything organised.
A10: DAILY WORKFLOW
C11: Morning | D11: Check 📊 DASHBOARD for your KPI snapshot. Review 📝 TASKS by priority.
C12: During Day | D12: Log expenses in 📤 EXPENSES as they occur. Mark ✓ in ✅ HABITS each evening.
C13: Evening | D13: Update task statuses. Log health in 🏃 HEALTH (weight, sleep, mood, exercise).
C14: Weekly | D14: Review 📋 BUDGET vs actuals. Update 🎯 GOALS progress %. Check 📊 ANALYTICS.
C15: Monthly | D15: Update 💰 NET WORTH history. Review 💼 WEALTH savings progress and debt.
A17: SHEET DIRECTORY
C18: 🔐 START | D18: Password splash screen — default password: life2025
C19: 🏠 HOME | D19: Navigation hub with cards linking to all 20 sheets
C20: ⚙️ SETUP | D20: Edit all dropdown lists that flow to every other sheet
C21: 📊 DASHBOARD | D21: Live KPI cards + Income/Expenses/Net Worth charts
C22: 📥 INCOME | D22: Log income with source category dropdown
C23: 📤 EXPENSES | D23: Track expenses with category dropdown + spending chart
C24: 📋 BUDGET | D24: Monthly budget planner with On Track / Over Budget status
C25: 💼 WEALTH | D25: Savings goals, debt tracker with payoff dates
C26: 📈 INVESTMENTS | D26: Portfolio holdings + 10-year compound growth forecast
C27: 💰 NET WORTH | D27: Asset/liability breakdown + historical net worth trend
C28: 🎯 GOALS | D28: 12-goal tracker with progress bars and chart
C29: ✅ HABITS | D29: 31-day daily habit grid with streaks and completion rate
... C37: 📖 USER GUIDE | D37: You are here!
A39: KEY FORMULAS
C40: SUMIF | D40: Sums amounts by category (Budget, Income/Expense summaries)
C41: COUNTIF | D41: Counts tasks by status, habits by completion mark
C42: IFERROR | D42: Wraps every formula to prevent errors when data is empty
C43: AVERAGE | D43: Health averages (weight, sleep, mood, exercise)
C44: FV | D44: Future Value — investment compound growth forecast
C45: EDATE | D45: Debt payoff date calculation based on payment + interest rate
C46: REPT | D46: Visual progress bars using █ and ░ characters in Savings sheet
C47: Dropdowns | D47: All category dropdowns reference lists in ⚙️ SETUP!B:I
A49: Life Management Dashboard • v2.0 • Password: life2025 • 20 Tabs
